<?xml version="1.0"?>
<robot xmlns:xacro="http://www.ros.org/wiki/xacro">
    <!-- Import all Gazebo customization elements including colors-->
    <xacro:include filename="$(find bbot_description)/urdf/bbot.gazebo.xacro"/>
    <!-- Import Transmissions -->
    <xacro:include filename="$(find bbot_description)/urdf/bbot.transmission.xacro" />
  
    <!-- Include Utilities -->

    <!--Define properties-->
    <xacro:property name="safety_controller_k_pos" value="100" />
    <xacro:property name="safety_controller_k_vel" value="2" /> 
    <xacro:property name="joint_damping" value="0.5" />
    <xacro:property name="max_effort" value="300"/>
    <xacro:property name="max_velocity" value="10"/>


    <xacro:macro name="bbot" params="parent hardware_interface robot_name *origin">
        <!-- joint between parent (a.k.a. world) and link_0 -->
        <joint name="${parent}_${robot_name}_joint" type="fixed">
            <xacro:insert_block name="origin"/>
            <parent link="${parent}"/>
            <child link="${robot_name}_link_baseplate"/>
        </joint>

        <link name="${robot_name}_link_baseplate">
            <inertial>
                <origin xyz="0 0 0" rpy="${pi/2.0} 0 0"/>
                <mass value="0.0800"/>
                <inertia ixx="0.000070" ixy="0" ixz="0" iyy="0.000174" iyz="0" izz="0.000107"/>
            </inertial>

            <visual>
                <origin xyz="0 0 0" rpy="${pi/2.0} 0 0"/>
                <geometry>
                    <mesh filename="package://bbot_description/meshes/baseplate.stl" scale="0.001 0.001 0.001"/>
                </geometry>
                <material name="Orange"/>
            </visual>

            <collision>
                <origin xyz="0 0 0" rpy="${pi/2.0} 0 0"/>
                <geometry>
                    <mesh filename="package://bbot_description/meshes/baseplate.stl" scale="0.001 0.001 0.001"/>
                </geometry>
                <material name="Orange"/>
            </collision>
        </link>

        <joint name="${robot_name}_joint_base_motor1" type="fixed">
            <parent link="${robot_name}_link_baseplate"/>
            <child link="${robot_name}_link_motor1"/>
            <origin xyz="0 0 0.0264" rpy="0 0 0"/>
        </joint>

        <link name="${robot_name}_link_motor1">
            <inertial>
                <origin xyz="0 0 0" rpy="0 0 ${pi/2.0}"/>
                <mass value="0.074"/>
                <inertia ixx="0.000031" ixy="0" ixz="0" iyy="0.000013" iyz="0" izz="0.000027"/>
            </inertial>

            <visual>
                <origin xyz="0 0 0" rpy="0 0 ${pi/2.0}"/>
                <geometry>
                    <mesh filename="package://bbot_description/meshes/motor_no_idler.stl" scale="0.001 0.001 0.001"/>
                </geometry>
                <material name="Black"/>
            </visual>

            <collision>
                <origin xyz="0 0 0" rpy="0 0 ${pi/2.0}"/>
                <geometry>
                    <mesh filename="package://bbot_description/meshes/motor_no_idler.stl" scale="0.001 0.001 0.001"/>
                </geometry>
                <material name="Black"/>
            </collision>
        </link>

        <joint name="${robot_name}_joint_1" type="revolute">
            <parent link="${robot_name}_link_motor1"/>
            <child link="${robot_name}_link1_2"/>
            <origin xyz="0 0 0.0205" rpy="0 0 0"/>
            <axis xyz="0 0 1"/>
            <limit lower="${-170 * pi / 180}" upper="${170 * pi / 180}"
                effort="${max_effort}" velocity="${max_velocity}" />
            <safety_controller soft_lower_limit="${-168 * pi / 180}"
                     soft_upper_limit="${168 * pi / 180}"
                     k_position="${safety_controller_k_pos}"
                     k_velocity="${safety_controller_k_vel}"/> 
            <dynamics damping="${joint_damping}"/>
        </joint>

        <link name="${robot_name}_link1_2">
            <inertial>
                <origin xyz="0 0 0" rpy="${pi/2.0} 0 ${pi/2.0}"/>
                <mass value="0.0296"/>
                <inertia ixx="0.000028" ixy="0" ixz="0" iyy="0.000014" iyz="0" izz="0.000023"/>
            </inertial>

            <visual>
                <origin xyz="0 0 0" rpy="${pi/2.0} 0 ${pi/2.0}"/>
                <geometry>
                    <mesh filename="package://bbot_description/meshes/link1_2.stl" scale="0.001 0.001 0.001"/>
                </geometry>
                <material name="Orange"/>
            </visual>

            <collision>
                <origin xyz="0 0 0" rpy="${pi/2.0} 0 ${pi/2.0}"/>
                <geometry>
                    <mesh filename="package://bbot_description/meshes/link1_2.stl" scale="0.001 0.001 0.001"/>
                </geometry>
                <material name="Orange"/>
            </collision>
        </link>

        <joint name="${robot_name}_joint_link1_2_motor2" type="fixed">
            <parent link="${robot_name}_link1_2"/>
            <child link="${robot_name}_link_motor2"/>
            <origin xyz="0 0 0.045" rpy="${pi/2.0} ${-pi/2.0} 0"/>
        </joint>

        <link name="${robot_name}_link_motor2">
            <inertial>
                <origin xyz="0 0 0" rpy="0 0 ${-pi/2.0}"/>
                <mass value="0.076"/>
                <inertia ixx="0.000031" ixy="0" ixz="0" iyy="0.000014" iyz="0" izz="0.000018"/>
            </inertial>

            <visual>
                <origin xyz="0 0 0" rpy="0 0 ${-pi/2.0}"/>
                <geometry>
                    <mesh filename="package://bbot_description/meshes/motor_with_idler.stl" scale="0.001 0.001 0.001"/>
                </geometry>
                <material name="Black"/>
            </visual>

            <collision>
                <origin xyz="0 0 0" rpy="0 0 ${-pi/2.0}"/>
                <geometry>
                    <mesh filename="package://bbot_description/meshes/motor_with_idler.stl" scale="0.001 0.001 0.001"/>
                </geometry>
                <material name="Black"/>
            </collision>
        </link>

        <joint name="${robot_name}_joint_2" type="revolute">
            <parent link="${robot_name}_link_motor2"/>
            <child link="${robot_name}_link2_3"/>
            <origin xyz="0 0 0" rpy="0 0 0"/>
            <axis xyz="0 0 1"/>
            <limit lower="${-170 * pi / 180}" upper="${170 * pi / 180}"
                effort="${max_effort}" velocity="${max_velocity}" />
            <safety_controller soft_lower_limit="${-168 * pi / 180}"
                     soft_upper_limit="${168 * pi / 180}"
                     k_position="${safety_controller_k_pos}"
                     k_velocity="${safety_controller_k_vel}"/> 
            <dynamics damping="${joint_damping}"/>
        </joint>

        <link name="${robot_name}_link2_3">
            <inertial>
                <origin xyz="0.0275 0 0" rpy="${pi/2.0} ${-pi/2.0} 0"/>
                <mass value="0.0584"/>
                <inertia ixx="0.000096" ixy="0" ixz="0" iyy="0.000021" iyz="0" izz="0.00011"/>
            </inertial>

            <visual>
                <origin xyz="0.0275 0 0" rpy="${pi/2.0} ${-pi/2.0} 0"/>
                <geometry>
                    <mesh filename="package://bbot_description/meshes/link2_3.stl" scale="0.001 0.001 0.001"/>
                </geometry>
                <material name="Orange"/>
            </visual>

            <collision>
                <origin xyz="0.0275 0 0" rpy="${pi/2.0} ${-pi/2.0} 0"/>
                <geometry>
                    <mesh filename="package://bbot_description/meshes/link2_3.stl" scale="0.001 0.001 0.001"/>
                </geometry>
                <material name="Orange"/>
            </collision>
        </link>

        <joint name="${robot_name}_joint_3" type="revolute">
            <parent link="${robot_name}_link2_3"/>
            <child link="${robot_name}_link_motor3"/>
            <origin xyz="0.105 0 0" rpy="0 0 0"/>
            <axis xyz="0 0 1"/>
            <limit lower="${-170 * pi / 180}" upper="${170 * pi / 180}"
                effort="${max_effort}" velocity="${max_velocity}" />
            <safety_controller soft_lower_limit="${-168 * pi / 180}"
                     soft_upper_limit="${168 * pi / 180}"
                     k_position="${safety_controller_k_pos}"
                     k_velocity="${safety_controller_k_vel}"/> 
            <dynamics damping="${joint_damping}"/>
        </joint>

        <link name="${robot_name}_link_motor3">
            <inertial>
                <origin xyz="0 0 0" rpy="0 0 ${pi/2.0}"/>
                <mass value="0.076"/>
                <inertia ixx="0.000031" ixy="0" ixz="0" iyy="0.000014" iyz="0" izz="0.000027"/>
            </inertial>

            <visual>
                <origin xyz="0 0 0" rpy="0 0 ${pi/2.0}"/>
                <geometry>
                    <mesh filename="package://bbot_description/meshes/motor_with_idler.stl" scale="0.001 0.001 0.001"/>
                </geometry>
                <material name="Black"/>
            </visual>

            <collision>
                <origin xyz="0 0 0" rpy="0 0 ${pi/2.0}"/>
                <geometry>
                    <mesh filename="package://bbot_description/meshes/motor_with_idler.stl" scale="0.001 0.001 0.001"/>
                </geometry>
                <material name="Black"/>
            </collision>
        </link>

        <joint name="${robot_name}_joint_motor3_link3_4" type="fixed">
            <parent link="${robot_name}_link_motor3"/>
            <child link="${robot_name}_link3_4"/>
            <origin xyz="0 0 0" rpy="0 0 0"/>
        </joint>

        <link name="${robot_name}_link3_4">
            <inertial>
                <origin xyz="0.067 0 0.01" rpy="0 0 0"/>
                <mass value="0.0409"/>
                <inertia ixx="0.000016" ixy="0" ixz="0" iyy="0.000053" iyz="0" izz="0.000049"/>
            </inertial>

            <visual>
                <origin xyz="0.067 0 0.01" rpy="0 0 0"/>
                <geometry>
                    <mesh filename="package://bbot_description/meshes/link3_4.stl" scale="0.001 0.001 0.001"/>
                </geometry>
                <material name="Orange"/>
            </visual>

            <collision>
                <origin xyz="0.067 0 0.01" rpy="0 0 0"/>
                <geometry>
                    <mesh filename="package://bbot_description/meshes/link3_4.stl" scale="0.001 0.001 0.001"/>
                </geometry>
                <material name="Orange"/>
            </collision>
        </link>

        <joint name="${robot_name}_joint_link3_4_motor4" type="fixed">
            <parent link="${robot_name}_link3_4"/>
            <child link="${robot_name}_link_motor4"/>
            <origin xyz="0.134 0 0" rpy="0 0 0"/>
        </joint>


        <link name="${robot_name}_link_motor4">
            <inertial>
                <origin xyz="0 0 0" rpy="0 0 ${-pi/2.0}"/>
                <mass value="0.076"/>
                <inertia ixx="0.000031" ixy="0" ixz="0" iyy="0.000014" iyz="0" izz="0.000027"/>
            </inertial>

            <visual>
                <origin xyz="0 0 0" rpy="0 0 ${-pi/2.0}"/>
                <geometry>
                    <mesh filename="package://bbot_description/meshes/motor_with_idler.stl" scale="0.001 0.001 0.001"/>
                </geometry>
                <material name="Black"/>
            </visual>

            <collision>
                <origin xyz="0 0 0" rpy="0 0 ${-pi/2.0}"/>
                <geometry>
                    <mesh filename="package://bbot_description/meshes/motor_with_idler.stl" scale="0.001 0.001 0.001"/>
                </geometry>
                <material name="Black"/>
            </collision>
        </link>

        <joint name="${robot_name}_joint_4" type="revolute">
            <parent link="${robot_name}_link_motor4"/>
            <child link="${robot_name}_link4_5"/>
            <origin xyz="0 0 0" rpy="0 0 0"/>
            <axis xyz="0 0 1"/>
            <limit lower="${-170 * pi / 180}" upper="${170 * pi / 180}"
                effort="${max_effort}" velocity="${max_velocity}" />
            <safety_controller soft_lower_limit="${-168 * pi / 180}"
                     soft_upper_limit="${168 * pi / 180}"
                     k_position="${safety_controller_k_pos}"
                     k_velocity="${safety_controller_k_vel}"/> 
            <dynamics damping="${joint_damping}"/>
        </joint>

        <link name="${robot_name}_link4_5">
            <inertial>
                <origin xyz="0 0 0.0235" rpy="0 0 0"/>
                <mass value="0.021"/>
                <inertia ixx="0.000016" ixy="0" ixz="0" iyy="0.000008" iyz="0" izz="0.00001"/>
            </inertial>

            <visual>
                <origin xyz="0 0 0.0235" rpy="0 0 0"/>
                <geometry>
                    <mesh filename="package://bbot_description/meshes/link4_5.stl" scale="0.001 0.001 0.001"/>
                </geometry>
                <material name="Orange"/>
            </visual>

            <collision>
                <origin xyz="0 0 0.0235" rpy="0 0 0"/>
                <geometry>
                    <mesh filename="package://bbot_description/meshes/link4_5.stl" scale="0.001 0.001 0.001"/>
                </geometry>
                <material name="Orange"/>
            </collision>
        </link>

        <joint name="${robot_name}_joint_5" type="revolute">
            <parent link="${robot_name}_link4_5"/>
            <child link="${robot_name}_link_motor5"/>
            <origin xyz="0 0 0.0625" rpy="${pi/2.0} ${-pi/2.0} 0"/>
            <axis xyz="0 0 1"/>
            <limit lower="${-170 * pi / 180}" upper="${170 * pi / 180}"
                effort="${max_effort}" velocity="${max_velocity}" />
            <safety_controller soft_lower_limit="${-168 * pi / 180}"
                     soft_upper_limit="${168 * pi / 180}"
                     k_position="${safety_controller_k_pos}"
                     k_velocity="${safety_controller_k_vel}"/> 
            <dynamics damping="${joint_damping}"/>
        </joint>

        <link name="${robot_name}_link_motor5">
            <inertial>
                <origin xyz="0 0 0" rpy="0 0 0"/>
                <mass value="0.076"/>
                <inertia ixx="0.000031" ixy="0" ixz="0" iyy="0.000014" iyz="0" izz="0.000027"/>
            </inertial>

            <visual>
                <origin xyz="0 0 0" rpy="0 0 0"/>
                <geometry>
                    <mesh filename="package://bbot_description/meshes/motor_with_idler.stl" scale="0.001 0.001 0.001"/>
                </geometry>
                <material name="Black"/>
            </visual>

            <collision>
                <origin xyz="0 0 0" rpy="0 0 0"/>
                <geometry>
                    <mesh filename="package://bbot_description/meshes/motor_with_idler.stl" scale="0.001 0.001 0.001"/>
                </geometry>
                <material name="Black"/>
            </collision>
        </link>

        <joint name="${robot_name}_joint_motor5_link5_6" type="fixed">
            <parent link="${robot_name}_link_motor5"/>
            <child link="${robot_name}_link5_6"/>
            <origin xyz="0 -0.0371 0" rpy="0 0 0"/>
        </joint>

        <link name="${robot_name}_link5_6">
            <inertial>
                <origin xyz="0 0 0.0173" rpy="${pi/2.0} 0 ${pi/2.0}"/>
                <mass value="0.01588"/>
                <inertia ixx="0.00001" ixy="0" ixz="0" iyy="0.000003" iyz="0" izz="0.000009"/>
            </inertial>

            <visual>
                <origin xyz="0 0 0.0173" rpy="${pi/2.0} 0 ${pi/2.0}"/>
                <geometry>
                    <mesh filename="package://bbot_description/meshes/link5_6.stl" scale="0.001 0.001 0.001"/>
                </geometry>
                <material name="Orange"/>
            </visual>

            <collision>
                <origin xyz="0 0 0.0173" rpy="${pi/2.0} 0 ${pi/2.0}"/>
                <geometry>
                    <mesh filename="package://bbot_description/meshes/link5_6.stl" scale="0.001 0.001 0.001"/>
                </geometry>
                <material name="Orange"/>
            </collision>
        </link>

        <joint name="${robot_name}_joint_6" type="revolute">
            <parent link="${robot_name}_link5_6"/>
            <child link="${robot_name}_link_motor6"/>
            <origin xyz="0 -0.0332 0" rpy="${pi/2.0} 0 0"/>
            <axis xyz="0 0 1"/>
            <limit lower="${-170 * pi / 180}" upper="${170 * pi / 180}"
                effort="${max_effort}" velocity="${max_velocity}" />
            <safety_controller soft_lower_limit="${-168 * pi / 180}"
                     soft_upper_limit="${168 * pi / 180}"
                     k_position="${safety_controller_k_pos}"
                     k_velocity="${safety_controller_k_vel}"/> 
            <dynamics damping="${joint_damping}"/>
        </joint>

        <link name="${robot_name}_link_motor6">
            <inertial>
                <origin xyz="0 0 0" rpy="0 0 ${pi}"/>
                <mass value="0.076"/>
                <inertia ixx="0.000031" ixy="0" ixz="0" iyy="0.000014" iyz="0" izz="0.000027"/>
            </inertial>

            <visual>
                <origin xyz="0 0 0" rpy="0 0 ${pi}"/>
                <geometry>
                    <mesh filename="package://bbot_description/meshes/motor_with_idler.stl" scale="0.001 0.001 0.001"/>
                </geometry>
                <material name="Black"/>
            </visual>

            <collision>
                <origin xyz="0 0 0" rpy="0 0 ${pi}"/>
                <geometry>
                    <mesh filename="package://bbot_description/meshes/motor_with_idler.stl" scale="0.001 0.001 0.001"/>
                </geometry>
                <material name="Black"/>
            </collision>
        </link>

        <!-- joint between motor6 and gripper_palm-->
        <joint name="${robot_name}_joint_motor6_gripper_palm" type="fixed">
            <parent link="${robot_name}_link_motor6"/>
            <child link="${robot_name}_gripper_palm"/>
            <origin xyz="0 0 0.015" rpy="0 0 0"/>
        </joint>
        <!-- link gripper_palm -->
        <link name="${robot_name}_gripper_palm">
            <inertial>
                <origin xyz="0 0 0.0073" rpy="${pi} 0 ${0.0}"/>
                <mass value="0.0646"/>
                <inertia ixx="0.000077" ixy="0.000001" ixz="-0.000001" iyy="0.000086" iyz="-0.00001" izz="0.000024"/>
            </inertial>

            <visual>
                <origin xyz="0 0 0.0073" rpy="${pi} 0 ${0.0}"/>
                <geometry>
                    <mesh filename="package://bbot_description/meshes/gripper_palm.stl" scale="0.001 0.001 0.001"/>
                </geometry>
                <material name="Orange"/>
            </visual>

            <collision>
                <origin xyz="0 0 0.0073" rpy="${pi} 0 ${0.0}"/>
                <geometry>
                    <mesh filename="package://bbot_description/meshes/gripper_palm.stl" scale="0.001 0.001 0.001"/>
                </geometry>
                <material name="Orange"/>
            </collision>
        </link>

        <!-- joint between gripper_palm and motor7 -->
        <joint name="${robot_name}_joint_gripper_palm_motor7" type="fixed">
            <parent link="${robot_name}_gripper_palm"/>
            <child link="${robot_name}_link_motor7"/>
            <origin xyz="0 0.2 0" rpy="0 0 0"/>
        </joint>

        <!-- motor 7 -->
        <link name="${robot_name}_link_motor7">
            <inertial>
                <origin xyz="0 0 0" rpy="0 0 ${pi}"/>
                <mass value="0.076"/>
                <inertia ixx="0.000031" ixy="0" ixz="0" iyy="0.000014" iyz="0" izz="0.000027"/>
            </inertial>

            <visual>
                <origin xyz="0 0 0" rpy="0 0 ${pi}"/>
                <geometry>
                    <mesh filename="package://bbot_description/meshes/motor_with_idler.stl" scale="0.001 0.001 0.001"/>
                </geometry>
                <material name="Black"/>
            </visual>

            <collision>
                <origin xyz="0 0 0" rpy="0 0 ${pi}"/>
                <geometry>
                    <mesh filename="package://bbot_description/meshes/motor_with_idler.stl" scale="0.001 0.001 0.001"/>
                </geometry>
                <material name="Black"/>
            </collision>
        </link>

        <!-- joint between motor 7 and link_claw1-->

        <!-- link_claw1 -->

        <xacro:bbot_gazebo robot_name="${robot_name}"/>
        <xacro:bbot_transmission hardware_interface="${hardware_interface}"/>
    </xacro:macro>

</robot>